Workbook

Sheet Assumptions
A1: הנחות יסוד - יוצאים מהמרוץ (תאים כחולים = קלט; כל שאר הגיליונות נוסחאות)
A3: מתג תרחיש (1=פסימי, 2=בסיס, 3=אופטימי) | C3: 2
A4: מתג שפה (1=עברית בלבד, 2=עברית+אנגלית) | C4: 2
A5: תרחיש פעיל (שם) | C5: =CHOOSE(C3,"פסימי","בסיס","אופטימי")
A7: הנחה | B7: יחידה | C7: פסימי | D7: בסיס | E7: אופטימי | F7: מקור / הערה
A8: מחירים (מקור: business/sales/pricing.md - מועתק מילה במילה)
A9: remove_ads - מחיר כולל מע"מ | B9: ₪ | C9: 14.9 | D9: 14.9 | E9: 14.9 | F9: pricing.md
A10: premium_pack - מחיר כולל מע"מ | B10: ₪ | C10: 19.9 | D10: 19.9 | E10: 19.9 | F10: pricing.md
A11: bundle_all - מחיר כולל מע"מ | B11: ₪ | C11: 29.9 | D11: 29.9 | E11: 29.9 | F11: pricing.md
A12: remove_ads - מחיר דולר | B12: $ | C12: 3.99 | D12: 3.99 | E12: 3.99 | F12: pricing.md
A13: premium_pack - מחיר דולר | B13: $ | C13: 4.99 | D13: 4.99 | E13: 4.99 | F13: pricing.md
A14: bundle_all - מחיר דולר | B14: $ | C14: 6.99 | D14: 6.99 | E14: 6.99 | F14: pricing.md
A15: B2B כיתה (לפני מע"מ, לשנה) | B15: ₪ | C15: 149 | D15: 149 | E15: 149 | F15: pricing.md
A16: B2B בית ספר (עד 12 כיתות) | B16: ₪ | C16: 450 | D16: 450 | E16: 450 | F16: pricing.md. מסלול רשת 350 לבית ספר לא מוּדל (שמרני)
A17: B2B תנועת נוער / עמותה | B17: ₪ | C17: 1200 | D17: 1200 | E17: 1200 | F17: pricing.md
A18: עמלות, מסים ושערים
A19: עמלת חנות | B19: % | C19: 0.15 | D19: 0.15 | E19: 0.15 | F19: pricing.md (small business 15%); לאמת תנאים עדכניים
A20: מע"מ ישראל (מחיר החנות כולל מע"מ) | B20: % | C20: 0.18 | D20: 0.18 | E20: 0.18 | F20: הנחה: 18%; לאמת. העמלה מחושבת על המחיר נטו
A21: ניכוי מסים ממוצע בשוק אנגלי (מכירה/VAT) | B21: % | C21: 0.1 | D21: 0.1 | E21: 0.1 | F21: estimate
A22: שער $ ל-₪ | B22: ₪/$ | C22: 3.6 | D22: 3.6 | E22: 3.6 | F22: estimate - לעדכן
A23: מיקס רכישות (מתוך הרוכשים)
A24: חלק remove_ads | B24: % | C24: 0.4 | D24: 0.4 | E24: 0.4 | F24: estimate
A25: חלק premium_pack | B25: % | C25: 0.25 | D25: 0.25 | E25: 0.25 | F25: estimate
A26: חלק bundle_all | B26: % | C26: 0.35 | D26: 0.35 | E26: 0.35 | F26: estimate; סכום חייב להיות 100%
A27: התקנות (אורגני)
A28: התקנות אורגניות בחודש - עברית (חודש 1) | B28: התקנות | C28: 200 | D28: 1000 | E28: 5000 | F28: unit-economics skill (estimate)
A29: צמיחה חודשית בהתקנות | B29: % | C29: 0 | D29: 0.02 | E29: 0.04 | F29: estimate
A30: התקנות אורגניות בחודש - אנגלית (מחודש ההשקה) | B30: התקנות | C30: 100 | D30: 500 | E30: 3000 | F30: estimate; שוק גדול אך תחרותי ובלי שיווק
A31: חודש השקת גרסה אנגלית | B31: חודש | C31: 4 | D31: 4 | E31: 4 | F31: estimate (דורש תרגום + i18n)
A32: עלות להתקנה בבדיקות פרסום בתשלום | B32: ₪ | C32: 3 | D32: 3 | E32: 3 | F32: estimate (ישראל, Android)
A33: תקציב פרסום בתשלום לחודש | B33: ₪ | C33: 500 | D33: 500 | E33: 1000 | F33: estimate; בדיקה קטנה בלבד
A34: חודש התחלת פרסום בתשלום | B34: חודש | C34: 2 | D34: 2 | E34: 2 | F34: estimate
A35: חודש סיום פרסום בתשלום | B35: חודש | C35: 3 | D35: 3 | E35: 3 | F35: estimate
A36: שימור ופעילות
A37: שימור D1 | B37: % | C37: 0.25 | D37: 0.35 | E37: 0.45 | F37: unit-economics skill (estimate)
A38: שימור D7 | B38: % | C38: 0.08 | D38: 0.12 | E38: 0.18 | F38: unit-economics skill (estimate)
A39: שימור D30 | B39: % | C39: 0.03 | D39: 0.05 | E39: 0.08 | F39: unit-economics skill (estimate)
A40: דעיכה חודשית של שחקנים ותיקים (מעבר לחודש 1) | B40: x | C40: 0.8 | D40: 0.85 | E40: 0.9 | F40: estimate
A41: משחקים ביום למשתמש פעיל (DAU) | B41: משחקים | C41: 1 | D41: 1.2 | E41: 1.5 | F41: estimate; משחק = 15-25 תורות
A42: פרסומות (כללי monetization.md: מתוגמלת עד 3 למשחק, ביניים עד 1 למשחק ולא בסשן ראשון)
...

Sheet Costs
A1: עלויות חודשיות (₪) - מזומן. נוסחאות בלבד; ערכים מ-Assumptions (עמודת בסיס, עלויות זהות בין תרחישים). פרסום בתשלום - בגיליונות Calc.
A3: חודש | B3: סה"כ 24 חודשים | C3: 1 | D3: 2 | E3: 3 | F3: 4 | G3: 5 | H3: 6 | I3: 7 | J3: 8 | K3: 9 | L3: 10 | M3: 11 | N3: 12 | O3: 13 | P3: 14 | Q3: 15 | R3: 16 | S3: 17 | T3: 18 | U3: 19 | V3: 20 | W3: 21 | X3: 22 | Y3: 23 | Z3: 24
A4: Google Play - חד-פעמי | B4: =SUM(C4:Z4) | C4: =IF(C$3=1,Assumptions!$D$60*Assumptions!$D$22,0) | D4: =IF(D$3=1,Assumptions!$D$60*Assumptions!$D$22,0) | E4: =IF(E$3=1,Assumptions!$D$60*Assumptions!$D$22,0) | F4: =IF(F$3=1,Assumptions!$D$60*Assumptions!$D$22,0) | G4: =IF(G$3=1,Assumptions!$D$60*Assumptions!$D$22,0) | H4: =IF(H$3=1,Assumptions!$D$60*Assumptions!$D$22,0) | I4: =IF(I$3=1,Assumptions!$D$60*Assumptions!$D$22,0) | J4: =IF(J$3=1,Assumptions!$D$60*Assumptions!$D$22,0) | ... Z4: =IF(Z$3=1,Assumptions!$D$60*Assumptions!$D$22,0)
A5: Apple Developer - שנתי | B5: =SUM(C5:Z5) | C5: =IF(MOD(C$3-1,12)=0,Assumptions!$D$61*Assumptions!$D$22,0) | D5: =IF(MOD(D$3-1,12)=0,Assumptions!$D$61*Assumptions!$D$22,0) | E5: =IF(MOD(E$3-1,12)=0,Assumptions!$D$61*Assumptions!$D$22,0) | F5: =IF(MOD(F$3-1,12)=0,Assumptions!$D$61*Assumptions!$D$22,0) | G5: =IF(MOD(G$3-1,12)=0,Assumptions!$D$61*Assumptions!$D$22,0) | H5: =IF(MOD(H$3-1,12)=0,Assumptions!$D$61*Assumptions!$D$22,0) | I5: =IF(MOD(I$3-1,12)=0,Assumptions!$D$61*Assumptions!$D$22,0) | J5: =IF(MOD(J$3-1,12)=0,Assumptions!$D$61*Assumptions!$D$22,0) | ... Z5: =IF(MOD(Z$3-1,12)=0,Assumptions!$D$61*Assumptions!$D$22,0)
A6: דומיין - שנתי | B6: =SUM(C6:Z6) | C6: =IF(MOD(C$3-1,12)=0,Assumptions!$D$62,0) | D6: =IF(MOD(D$3-1,12)=0,Assumptions!$D$62,0) | E6: =IF(MOD(E$3-1,12)=0,Assumptions!$D$62,0) | F6: =IF(MOD(F$3-1,12)=0,Assumptions!$D$62,0) | G6: =IF(MOD(G$3-1,12)=0,Assumptions!$D$62,0) | H6: =IF(MOD(H$3-1,12)=0,Assumptions!$D$62,0) | I6: =IF(MOD(I$3-1,12)=0,Assumptions!$D$62,0) | J6: =IF(MOD(J$3-1,12)=0,Assumptions!$D$62,0) | ... Z6: =IF(MOD(Z$3-1,12)=0,Assumptions!$D$62,0)
A7: גישת בנייה ל-iOS | B7: =SUM(C7:Z7) | C7: =Assumptions!$D$63 | D7: =Assumptions!$D$63 | E7: =Assumptions!$D$63 | F7: =Assumptions!$D$63 | G7: =Assumptions!$D$63 | H7: =Assumptions!$D$63 | I7: =Assumptions!$D$63 | J7: =Assumptions!$D$63 | ... Z7: =Assumptions!$D$63
A8: נכסי עיצוב (אופציונלי) | B8: =SUM(C8:Z8) | C8: =IF(C$3=1,Assumptions!$D$64*Assumptions!$D$65,0) | D8: =IF(D$3=1,Assumptions!$D$64*Assumptions!$D$65,0) | E8: =IF(E$3=1,Assumptions!$D$64*Assumptions!$D$65,0) | F8: =IF(F$3=1,Assumptions!$D$64*Assumptions!$D$65,0) | G8: =IF(G$3=1,Assumptions!$D$64*Assumptions!$D$65,0) | H8: =IF(H$3=1,Assumptions!$D$64*Assumptions!$D$65,0) | I8: =IF(I$3=1,Assumptions!$D$64*Assumptions!$D$65,0) | J8: =IF(J$3=1,Assumptions!$D$64*Assumptions!$D$65,0) | ... Z8: =IF(Z$3=1,Assumptions!$D$64*Assumptions!$D$65,0)
A9: הנהלת חשבונות | B9: =SUM(C9:Z9) | C9: =Assumptions!$D$66 | D9: =Assumptions!$D$66 | E9: =Assumptions!$D$66 | F9: =Assumptions!$D$66 | G9: =Assumptions!$D$66 | H9: =Assumptions!$D$66 | I9: =Assumptions!$D$66 | J9: =Assumptions!$D$66 | ... Z9: =Assumptions!$D$66
A10: חומרי B2B | B10: =SUM(C10:Z10) | C10: =IF(C$3=1,Assumptions!$D$67,0) | D10: =IF(D$3=1,Assumptions!$D$67,0) | E10: =IF(E$3=1,Assumptions!$D$67,0) | F10: =IF(F$3=1,Assumptions!$D$67,0) | G10: =IF(G$3=1,Assumptions!$D$67,0) | H10: =IF(H$3=1,Assumptions!$D$67,0) | I10: =IF(I$3=1,Assumptions!$D$67,0) | J10: =IF(J$3=1,Assumptions!$D$67,0) | ... Z10: =IF(Z$3=1,Assumptions!$D$67,0)
A11: סה"כ עלויות קבועות (ללא פרסום בתשלום) | B11: =SUM(C11:Z11) | C11: =SUM(C4:C10) | D11: =SUM(D4:D10) | E11: =SUM(E4:E10) | F11: =SUM(F4:F10) | G11: =SUM(G4:G10) | H11: =SUM(H4:H10) | I11: =SUM(I4:I10) | J11: =SUM(J4:J10) | ... Z11: =SUM(Z4:Z10)
A12: תרגום לאנגלית (רק במתג עברית+אנגלית) | B12: =SUM(C12:Z12) | C12: =IF(C$3=Assumptions!$D$31-1,Assumptions!$D$68,0) | D12: =IF(D$3=Assumptions!$D$31-1,Assumptions!$D$68,0) | E12: =IF(E$3=Assumptions!$D$31-1,Assumptions!$D$68,0) | F12: =IF(F$3=Assumptions!$D$31-1,Assumptions!$D$68,0) | G12: =IF(G$3=Assumptions!$D$31-1,Assumptions!$D$68,0) | H12: =IF(H$3=Assumptions!$D$31-1,Assumptions!$D$68,0) | I12: =IF(I$3=Assumptions!$D$31-1,Assumptions!$D$68,0) | J12: =IF(J$3=Assumptions!$D$31-1,Assumptions!$D$68,0) | ... Z12: =IF(Z$3=Assumptions!$D$31-1,Assumptions!$D$68,0)
A14: ממו: שעות פיתוח | B14: =SUM(C14:Z14) | C14: =IF(C$3=1,Assumptions!$D$69,0)+Assumptions!$D$70 | D14: =IF(D$3=1,Assumptions!$D$69,0)+Assumptions!$D$70 | E14: =IF(E$3=1,Assumptions!$D$69,0)+Assumptions!$D$70 | F14: =IF(F$3=1,Assumptions!$D$69,0)+Assumptions!$D$70 | G14: =IF(G$3=1,Assumptions!$D$69,0)+Assumptions!$D$70 | H14: =IF(H$3=1,Assumptions!$D$69,0)+Assumptions!$D$70 | I14: =IF(I$3=1,Assumptions!$D$69,0)+Assumptions!$D$70 | J14: =IF(J$3=1,Assumptions!$D$69,0)+Assumptions!$D$70 | ... Z14: =IF(Z$3=1,Assumptions!$D$69,0)+Assumptions!$D$70
A15: ממו: ערך זמן פיתוח (₪) | B15: =SUM(C15:Z15) | C15: =C14*Assumptions!$D$71 | D15: =D14*Assumptions!$D$71 | E15: =E14*Assumptions!$D$71 | F15: =F14*Assumptions!$D$71 | G15: =G14*Assumptions!$D$71 | H15: =H14*Assumptions!$D$71 | I15: =I14*Assumptions!$D$71 | J15: =J14*Assumptions!$D$71 | ... Z15: =Z14*Assumptions!$D$71
A17: עלות השקה (12 חודשים ראשונים, מזומן, ללא פרסום בתשלום וללא אנגלית) | B17: =SUM(C11:N11)

Sheet Revenue
A1: הכנסות - תרחיש פעיל (לפי המתגים ב-Assumptions)
A2: ="תרחיש: "&Assumptions!C5&" | שפה: "&IF(Assumptions!C4=2,"עברית+אנגלית","עברית בלבד")
A3: חודש | B3: סה"כ | C3: 1 | D3: 2 | E3: 3 | F3: 4 | G3: 5 | H3: 6 | I3: 7 | J3: 8 | K3: 9 | L3: 10 | M3: 11 | N3: 12 | O3: 13 | P3: 14 | Q3: 15 | R3: 16 | S3: 17 | T3: 18 | U3: 19 | V3: 20 | W3: 21 | X3: 22 | Y3: 23 | Z3: 24
A4: התקנות - עברית | B4: =SUM(C4:Z4) | C4: =CHOOSE(Assumptions!$C$3,Calc_Pess!C8,Calc_Base!C8,Calc_Opt!C8) | D4: =CHOOSE(Assumptions!$C$3,Calc_Pess!D8,Calc_Base!D8,Calc_Opt!D8) | E4: =CHOOSE(Assumptions!$C$3,Calc_Pess!E8,Calc_Base!E8,Calc_Opt!E8) | F4: =CHOOSE(Assumptions!$C$3,Calc_Pess!F8,Calc_Base!F8,Calc_Opt!F8) | G4: =CHOOSE(Assumptions!$C$3,Calc_Pess!G8,Calc_Base!G8,Calc_Opt!G8) | H4: =CHOOSE(Assumptions!$C$3,Calc_Pess!H8,Calc_Base!H8,Calc_Opt!H8) | I4: =CHOOSE(Assumptions!$C$3,Calc_Pess!I8,Calc_Base!I8,Calc_Opt!I8) | J4: =CHOOSE(Assumptions!$C$3,Calc_Pess!J8,Calc_Base!J8,Calc_Opt!J8) | ... Z4: =CHOOSE(Assumptions!$C$3,Calc_Pess!Z8,Calc_Base!Z8,Calc_Opt!Z8)
A5: התקנות - אנגלית | B5: =SUM(C5:Z5) | C5: =IF(Assumptions!$C$4=2,CHOOSE(Assumptions!$C$3,Calc_Pess!C28,Calc_Base!C28,Calc_Opt!C28),0) | D5: =IF(Assumptions!$C$4=2,CHOOSE(Assumptions!$C$3,Calc_Pess!D28,Calc_Base!D28,Calc_Opt!D28),0) | E5: =IF(Assumptions!$C$4=2,CHOOSE(Assumptions!$C$3,Calc_Pess!E28,Calc_Base!E28,Calc_Opt!E28),0) | F5: =IF(Assumptions!$C$4=2,CHOOSE(Assumptions!$C$3,Calc_Pess!F28,Calc_Base!F28,Calc_Opt!F28),0) | G5: =IF(Assumptions!$C$4=2,CHOOSE(Assumptions!$C$3,Calc_Pess!G28,Calc_Base!G28,Calc_Opt!G28),0) | H5: =IF(Assumptions!$C$4=2,CHOOSE(Assumptions!$C$3,Calc_Pess!H28,Calc_Base!H28,Calc_Opt!H28),0) | I5: =IF(Assumptions!$C$4=2,CHOOSE(Assumptions!$C$3,Calc_Pess!I28,Calc_Base!I28,Calc_Opt!I28),0) | J5: =IF(Assumptions!$C$4=2,CHOOSE(Assumptions!$C$3,Calc_Pess!J28,Calc_Base!J28,Calc_Opt!J28),0) | ... Z5: =IF(Assumptions!$C$4=2,CHOOSE(Assumptions!$C$3,Calc_Pess!Z28,Calc_Base!Z28,Calc_Opt!Z28),0)
A6: DAU - עברית | B6: =SUM(C6:Z6) | C6: =CHOOSE(Assumptions!$C$3,Calc_Pess!C10,Calc_Base!C10,Calc_Opt!C10) | D6: =CHOOSE(Assumptions!$C$3,Calc_Pess!D10,Calc_Base!D10,Calc_Opt!D10) | E6: =CHOOSE(Assumptions!$C$3,Calc_Pess!E10,Calc_Base!E10,Calc_Opt!E10) | F6: =CHOOSE(Assumptions!$C$3,Calc_Pess!F10,Calc_Base!F10,Calc_Opt!F10) | G6: =CHOOSE(Assumptions!$C$3,Calc_Pess!G10,Calc_Base!G10,Calc_Opt!G10) | H6: =CHOOSE(Assumptions!$C$3,Calc_Pess!H10,Calc_Base!H10,Calc_Opt!H10) | I6: =CHOOSE(Assumptions!$C$3,Calc_Pess!I10,Calc_Base!I10,Calc_Opt!I10) | J6: =CHOOSE(Assumptions!$C$3,Calc_Pess!J10,Calc_Base!J10,Calc_Opt!J10) | ... Z6: =CHOOSE(Assumptions!$C$3,Calc_Pess!Z10,Calc_Base!Z10,Calc_Opt!Z10)
A7: DAU - אנגלית | B7: =SUM(C7:Z7) | C7: =IF(Assumptions!$C$4=2,CHOOSE(Assumptions!$C$3,Calc_Pess!C30,Calc_Base!C30,Calc_Opt!C30),0) | D7: =IF(Assumptions!$C$4=2,CHOOSE(Assumptions!$C$3,Calc_Pess!D30,Calc_Base!D30,Calc_Opt!D30),0) | E7: =IF(Assumptions!$C$4=2,CHOOSE(Assumptions!$C$3,Calc_Pess!E30,Calc_Base!E30,Calc_Opt!E30),0) | F7: =IF(Assumptions!$C$4=2,CHOOSE(Assumptions!$C$3,Calc_Pess!F30,Calc_Base!F30,Calc_Opt!F30),0) | G7: =IF(Assumptions!$C$4=2,CHOOSE(Assumptions!$C$3,Calc_Pess!G30,Calc_Base!G30,Calc_Opt!G30),0) | H7: =IF(Assumptions!$C$4=2,CHOOSE(Assumptions!$C$3,Calc_Pess!H30,Calc_Base!H30,Calc_Opt!H30),0) | I7: =IF(Assumptions!$C$4=2,CHOOSE(Assumptions!$C$3,Calc_Pess!I30,Calc_Base!I30,Calc_Opt!I30),0) | J7: =IF(Assumptions!$C$4=2,CHOOSE(Assumptions!$C$3,Calc_Pess!J30,Calc_Base!J30,Calc_Opt!J30),0) | ... Z7: =IF(Assumptions!$C$4=2,CHOOSE(Assumptions!$C$3,Calc_Pess!Z30,Calc_Base!Z30,Calc_Opt!Z30),0)
A8: פרסום (₪) - עברית | B8: =SUM(C8:Z8) | C8: =CHOOSE(Assumptions!$C$3,Calc_Pess!C15,Calc_Base!C15,Calc_Opt!C15) | D8: =CHOOSE(Assumptions!$C$3,Calc_Pess!D15,Calc_Base!D15,Calc_Opt!D15) | E8: =CHOOSE(Assumptions!$C$3,Calc_Pess!E15,Calc_Base!E15,Calc_Opt!E15) | F8: =CHOOSE(Assumptions!$C$3,Calc_Pess!F15,Calc_Base!F15,Calc_Opt!F15) | G8: =CHOOSE(Assumptions!$C$3,Calc_Pess!G15,Calc_Base!G15,Calc_Opt!G15) | H8: =CHOOSE(Assumptions!$C$3,Calc_Pess!H15,Calc_Base!H15,Calc_Opt!H15) | I8: =CHOOSE(Assumptions!$C$3,Calc_Pess!I15,Calc_Base!I15,Calc_Opt!I15) | J8: =CHOOSE(Assumptions!$C$3,Calc_Pess!J15,Calc_Base!J15,Calc_Opt!J15) | ... Z8: =CHOOSE(Assumptions!$C$3,Calc_Pess!Z15,Calc_Base!Z15,Calc_Opt!Z15)
A9: פרסום (₪) - אנגלית | B9: =SUM(C9:Z9) | C9: =IF(Assumptions!$C$4=2,CHOOSE(Assumptions!$C$3,Calc_Pess!C35,Calc_Base!C35,Calc_Opt!C35),0) | D9: =IF(Assumptions!$C$4=2,CHOOSE(Assumptions!$C$3,Calc_Pess!D35,Calc_Base!D35,Calc_Opt!D35),0) | E9: =IF(Assumptions!$C$4=2,CHOOSE(Assumptions!$C$3,Calc_Pess!E35,Calc_Base!E35,Calc_Opt!E35),0) | F9: =IF(Assumptions!$C$4=2,CHOOSE(Assumptions!$C$3,Calc_Pess!F35,Calc_Base!F35,Calc_Opt!F35),0) | G9: =IF(Assumptions!$C$4=2,CHOOSE(Assumptions!$C$3,Calc_Pess!G35,Calc_Base!G35,Calc_Opt!G35),0) | H9: =IF(Assumptions!$C$4=2,CHOOSE(Assumptions!$C$3,Calc_Pess!H35,Calc_Base!H35,Calc_Opt!H35),0) | I9: =IF(Assumptions!$C$4=2,CHOOSE(Assumptions!$C$3,Calc_Pess!I35,Calc_Base!I35,Calc_Opt!I35),0) | J9: =IF(Assumptions!$C$4=2,CHOOSE(Assumptions!$C$3,Calc_Pess!J35,Calc_Base!J35,Calc_Opt!J35),0) | ... Z9: =IF(Assumptions!$C$4=2,CHOOSE(Assumptions!$C$3,Calc_Pess!Z35,Calc_Base!Z35,Calc_Opt!Z35),0)
A10: IAP נטו (₪) - עברית | B10: =SUM(C10:Z10) | C10: =CHOOSE(Assumptions!$C$3,Calc_Pess!C18,Calc_Base!C18,Calc_Opt!C18) | D10: =CHOOSE(Assumptions!$C$3,Calc_Pess!D18,Calc_Base!D18,Calc_Opt!D18) | E10: =CHOOSE(Assumptions!$C$3,Calc_Pess!E18,Calc_Base!E18,Calc_Opt!E18) | F10: =CHOOSE(Assumptions!$C$3,Calc_Pess!F18,Calc_Base!F18,Calc_Opt!F18) | G10: =CHOOSE(Assumptions!$C$3,Calc_Pess!G18,Calc_Base!G18,Calc_Opt!G18) | H10: =CHOOSE(Assumptions!$C$3,Calc_Pess!H18,Calc_Base!H18,Calc_Opt!H18) | I10: =CHOOSE(Assumptions!$C$3,Calc_Pess!I18,Calc_Base!I18,Calc_Opt!I18) | J10: =CHOOSE(Assumptions!$C$3,Calc_Pess!J18,Calc_Base!J18,Calc_Opt!J18) | ... Z10: =CHOOSE(Assumptions!$C$3,Calc_Pess!Z18,Calc_Base!Z18,Calc_Opt!Z18)
A11: IAP נטו (₪) - אנגלית | B11: =SUM(C11:Z11) | C11: =IF(Assumptions!$C$4=2,CHOOSE(Assumptions!$C$3,Calc_Pess!C38,Calc_Base!C38,Calc_Opt!C38),0) | D11: =IF(Assumptions!$C$4=2,CHOOSE(Assumptions!$C$3,Calc_Pess!D38,Calc_Base!D38,Calc_Opt!D38),0) | E11: =IF(Assumptions!$C$4=2,CHOOSE(Assumptions!$C$3,Calc_Pess!E38,Calc_Base!E38,Calc_Opt!E38),0) | F11: =IF(Assumptions!$C$4=2,CHOOSE(Assumptions!$C$3,Calc_Pess!F38,Calc_Base!F38,Calc_Opt!F38),0) | G11: =IF(Assumptions!$C$4=2,CHOOSE(Assumptions!$C$3,Calc_Pess!G38,Calc_Base!G38,Calc_Opt!G38),0) | H11: =IF(Assumptions!$C$4=2,CHOOSE(Assumptions!$C$3,Calc_Pess!H38,Calc_Base!H38,Calc_Opt!H38),0) | I11: =IF(Assumptions!$C$4=2,CHOOSE(Assumptions!$C$3,Calc_Pess!I38,Calc_Base!I38,Calc_Opt!I38),0) | J11: =IF(Assumptions!$C$4=2,CHOOSE(Assumptions!$C$3,Calc_Pess!J38,Calc_Base!J38,Calc_Opt!J38),0) | ... Z11: =IF(Assumptions!$C$4=2,CHOOSE(Assumptions!$C$3,Calc_Pess!Z38,Calc_Base!Z38,Calc_Opt!Z38),0)
A12: B2B (₪) | B12: =SUM(C12:Z12) | C12: =CHOOSE(Assumptions!$C$3,Calc_Pess!C22,Calc_Base!C22,Calc_Opt!C22) | D12: =CHOOSE(Assumptions!$C$3,Calc_Pess!D22,Calc_Base!D22,Calc_Opt!D22) | E12: =CHOOSE(Assumptions!$C$3,Calc_Pess!E22,Calc_Base!E22,Calc_Opt!E22) | F12: =CHOOSE(Assumptions!$C$3,Calc_Pess!F22,Calc_Base!F22,Calc_Opt!F22) | G12: =CHOOSE(Assumptions!$C$3,Calc_Pess!G22,Calc_Base!G22,Calc_Opt!G22) | H12: =CHOOSE(Assumptions!$C$3,Calc_Pess!H22,Calc_Base!H22,Calc_Opt!H22) | I12: =CHOOSE(Assumptions!$C$3,Calc_Pess!I22,Calc_Base!I22,Calc_Opt!I22) | J12: =CHOOSE(Assumptions!$C$3,Calc_Pess!J22,Calc_Base!J22,Calc_Opt!J22) | ... Z12: =CHOOSE(Assumptions!$C$3,Calc_Pess!Z22,Calc_Base!Z22,Calc_Opt!Z22)
A13: סה"כ הכנסות (₪) | B13: =SUM(C13:Z13) | C13: =C8+C9+C10+C11+C12 | D13: =D8+D9+D10+D11+D12 | E13: =E8+E9+E10+E11+E12 | F13: =F8+F9+F10+F11+F12 | G13: =G8+G9+G10+G11+G12 | H13: =H8+H9+H10+H11+H12 | I13: =I8+I9+I10+I11+I12 | J13: =J8+J9+J10+J11+J12 | ... Z13: =Z8+Z9+Z10+Z11+Z12
A14: עלויות מזומן (₪) | B14: =SUM(C14:Z14) | C14: =IF(Assumptions!$C$4=2,CHOOSE(Assumptions!$C$3,Calc_Pess!C45,Calc_Base!C45,Calc_Opt!C45),CHOOSE(Assumptions!$C$3,Calc_Pess!C44,Calc_Base!C44,Calc_Opt!C44)) | D14: =IF(Assumptions!$C$4=2,CHOOSE(Assumptions!$C$3,Calc_Pess!D45,Calc_Base!D45,Calc_Opt!D45),CHOOSE(Assumptions!$C$3,Calc_Pess!D44,Calc_Base!D44,Calc_Opt!D44)) | E14: =IF(Assumptions!$C$4=2,CHOOSE(Assumptions!$C$3,Calc_Pess!E45,Calc_Base!E45,Calc_Opt!E45),CHOOSE(Assumptions!$C$3,Calc_Pess!E44,Calc_Base!E44,Calc_Opt!E44)) | F14: =IF(Assumptions!$C$4=2,CHOOSE(Assumptions!$C$3,Calc_Pess!F45,Calc_Base!F45,Calc_Opt!F45),CHOOSE(Assumptions!$C$3,Calc_Pess!F44,Calc_Base!F44,Calc_Opt!F44)) | G14: =IF(Assumptions!$C$4=2,CHOOSE(Assumptions!$C$3,Calc_Pess!G45,Calc_Base!G45,Calc_Opt!G45),CHOOSE(Assumptions!$C$3,Calc_Pess!G44,Calc_Base!G44,Calc_Opt!G44)) | H14: =IF(Assumptions!$C$4=2,CHOOSE(Assumptions!$C$3,Calc_Pess!H45,Calc_Base!H45,Calc_Opt!H45),CHOOSE(Assumptions!$C$3,Calc_Pess!H44,Calc_Base!H44,Calc_Opt!H44)) | I14: =IF(Assumptions!$C$4=2,CHOOSE(Assumptions!$C$3,Calc_Pess!I45,Calc_Base!I45,Calc_Opt!I45),CHOOSE(Assumptions!$C$3,Calc_Pess!I44,Calc_Base!I44,Calc_Opt!I44)) | J14: =IF(Assumptions!$C$4=2,CHOOSE(Assumptions!$C$3,Calc_Pess!J45,Calc_Base!J45,Calc_Opt!J45),CHOOSE(Assumptions!$C$3,Calc_Pess!J44,Calc_Base!J44,Calc_Opt!J44)) | ... Z14: =IF(Assumptions!$C$4=2,CHOOSE(Assumptions!$C$3,Calc_Pess!Z45,Calc_Base!Z45,Calc_Opt!Z45),CHOOSE(Assumptions!$C$3,Calc_Pess!Z44,Calc_Base!Z44,Calc_Opt!Z44))
A15: נטו חודשי (₪) | B15: =SUM(C15:Z15) | C15: =C13-C14 | D15: =D13-D14 | E15: =E13-E14 | F15: =F13-F14 | G15: =G13-G14 | H15: =H13-H14 | I15: =I13-I14 | J15: =J13-J14 | ... Z15: =Z13-Z14
A16: נטו מצטבר (₪) | C16: =C15 | D16: =C16+D15 | E16: =D16+E15 | F16: =E16+F15 | G16: =F16+G15 | H16: =G16+H15 | I16: =H16+I15 | J16: =I16+J15 | K16: =J16+K15 | ... Z16: =Y16+Z15
A18: הכנסות 12 חודשים ראשונים (₪) | B18: =SUM(C13:N13)
A19: נטו 12 חודשים ראשונים (₪) | B19: =SUM(C15:N15)
A20: חודש איזון (מצטבר >=0) | B20: =IFERROR(INDEX(C3:Z3,MATCH(1,INDEX(--(C16:Z16>=0),0),0)),"לא בתוך 24 חודשים")

Sheet Scenarios
A1: תרחישים - כל השישה במקביל (₪)
A3: תרחיש | B3: שפה | C3: התקנות 12 חו' | D3: הכנסות 12 חו' | E3: עלויות מזומן 12 חו' | F3: נטו 12 חו' | G3: הכנסה חודשית בחודש 12 | H3: נטו מצטבר 24 חו' | I3: חודש איזון (מזומן) | J3: חודש איזון כולל זמן פיתוח
A4: פסימי | B4: עברית בלבד | C4: =SUM(Calc_Pess!C8:N8) | D4: =SUM(Calc_Pess!C41:N41) | E4: =SUM(Calc_Pess!C44:N44) | F4: =D4-E4 | G4: =Calc_Pess!N41 | H4: =Calc_Pess!Z48 | I4: =Calc_Pess!B52 | J4: =Calc_Pess!B54
A5: פסימי | B5: עברית+אנגלית | C5: =SUM(Calc_Pess!C8:N8)+SUM(Calc_Pess!C28:N28) | D5: =SUM(Calc_Pess!C43:N43) | E5: =SUM(Calc_Pess!C45:N45) | F5: =D5-E5 | G5: =Calc_Pess!N43 | H5: =Calc_Pess!Z49 | I5: =Calc_Pess!B53 | J5: =Calc_Pess!B55
A6: בסיס | B6: עברית בלבד | C6: =SUM(Calc_Base!C8:N8) | D6: =SUM(Calc_Base!C41:N41) | E6: =SUM(Calc_Base!C44:N44) | F6: =D6-E6 | G6: =Calc_Base!N41 | H6: =Calc_Base!Z48 | I6: =Calc_Base!B52 | J6: =Calc_Base!B54
A7: בסיס | B7: עברית+אנגלית | C7: =SUM(Calc_Base!C8:N8)+SUM(Calc_Base!C28:N28) | D7: =SUM(Calc_Base!C43:N43) | E7: =SUM(Calc_Base!C45:N45) | F7: =D7-E7 | G7: =Calc_Base!N43 | H7: =Calc_Base!Z49 | I7: =Calc_Base!B53 | J7: =Calc_Base!B55
A8: אופטימי | B8: עברית בלבד | C8: =SUM(Calc_Opt!C8:N8) | D8: =SUM(Calc_Opt!C41:N41) | E8: =SUM(Calc_Opt!C44:N44) | F8: =D8-E8 | G8: =Calc_Opt!N41 | H8: =Calc_Opt!Z48 | I8: =Calc_Opt!B52 | J8: =Calc_Opt!B54
A9: אופטימי | B9: עברית+אנגלית | C9: =SUM(Calc_Opt!C8:N8)+SUM(Calc_Opt!C28:N28) | D9: =SUM(Calc_Opt!C43:N43) | E9: =SUM(Calc_Opt!C45:N45) | F9: =D9-E9 | G9: =Calc_Opt!N43 | H9: =Calc_Opt!Z49 | I9: =Calc_Opt!B53 | J9: =Calc_Opt!B55
A11: נטו מצטבר לפי חודש (לגרף)
A12: חודש | B12: 1 | C12: 2 | D12: 3 | E12: 4 | F12: 5 | G12: 6 | H12: 7 | I12: 8 | J12: 9 | K12: 10 | L12: 11 | M12: 12 | N12: 13 | O12: 14 | P12: 15 | Q12: 16 | R12: 17 | S12: 18 | T12: 19 | U12: 20 | V12: 21 | W12: 22 | X12: 23 | Y12: 24
A13: פסימי - עברית בלבד | B13: =Calc_Pess!C48 | C13: =Calc_Pess!D48 | D13: =Calc_Pess!E48 | E13: =Calc_Pess!F48 | F13: =Calc_Pess!G48 | G13: =Calc_Pess!H48 | H13: =Calc_Pess!I48 | I13: =Calc_Pess!J48 | ... Y13: =Calc_Pess!Z48
A14: פסימי - עברית+אנגלית | B14: =Calc_Pess!C49 | C14: =Calc_Pess!D49 | D14: =Calc_Pess!E49 | E14: =Calc_Pess!F49 | F14: =Calc_Pess!G49 | G14: =Calc_Pess!H49 | H14: =Calc_Pess!I49 | I14: =Calc_Pess!J49 | ... Y14: =Calc_Pess!Z49
A15: בסיס - עברית בלבד | B15: =Calc_Base!C48 | C15: =Calc_Base!D48 | D15: =Calc_Base!E48 | E15: =Calc_Base!F48 | F15: =Calc_Base!G48 | G15: =Calc_Base!H48 | H15: =Calc_Base!I48 | I15: =Calc_Base!J48 | ... Y15: =Calc_Base!Z48
A16: בסיס - עברית+אנגלית | B16: =Calc_Base!C49 | C16: =Calc_Base!D49 | D16: =Calc_Base!E49 | E16: =Calc_Base!F49 | F16: =Calc_Base!G49 | G16: =Calc_Base!H49 | H16: =Calc_Base!I49 | I16: =Calc_Base!J49 | ... Y16: =Calc_Base!Z49
A17: אופטימי - עברית בלבד | B17: =Calc_Opt!C48 | C17: =Calc_Opt!D48 | D17: =Calc_Opt!E48 | E17: =Calc_Opt!F48 | F17: =Calc_Opt!G48 | G17: =Calc_Opt!H48 | H17: =Calc_Opt!I48 | I17: =Calc_Opt!J48 | ... Y17: =Calc_Opt!Z48
A18: אופטימי - עברית+אנגלית | B18: =Calc_Opt!C49 | C18: =Calc_Opt!D49 | D18: =Calc_Opt!E49 | E18: =Calc_Opt!F49 | F18: =Calc_Opt!G49 | G18: =Calc_Opt!H49 | H18: =Calc_Opt!I49 | I18: =Calc_Opt!J49 | ... Y18: =Calc_Opt!Z49

Sheet BreakEven
A1: חודש איזון - החודש הראשון שבו הנטו המצטבר >= 0
A3: תרחיש | B3: שפה | C3: איזון - מזומן בלבד | D3: איזון - כולל ערך זמן פיתוח (ממו)
A4: =Scenarios!A4 | B4: =Scenarios!B4 | C4: =Scenarios!I4 | D4: =Scenarios!J4
A5: =Scenarios!A5 | B5: =Scenarios!B5 | C5: =Scenarios!I5 | D5: =Scenarios!J5
A6: =Scenarios!A6 | B6: =Scenarios!B6 | C6: =Scenarios!I6 | D6: =Scenarios!J6
A7: =Scenarios!A7 | B7: =Scenarios!B7 | C7: =Scenarios!I7 | D7: =Scenarios!J7
A8: =Scenarios!A8 | B8: =Scenarios!B8 | C8: =Scenarios!I8 | D8: =Scenarios!J8
A9: =Scenarios!A9 | B9: =Scenarios!B9 | C9: =Scenarios!I9 | D9: =Scenarios!J9
A11: התרחיש הפעיל (מתגים ב-Assumptions)
A12: חודש איזון מזומן | C12: =INDEX(C4:C9,(Assumptions!C3-1)*2+Assumptions!C4)
A13: חודש איזון כולל זמן פיתוח | C13: =INDEX(D4:D9,(Assumptions!C3-1)*2+Assumptions!C4)
A15: הערה: זמן פיתוח הוא ממו בלבד ולא עלות מזומן. הנטו לפני מס הכנסה (עוסק פטור - לבדוק תקרה שנתית).

Sheet Calc_Pess
A1: חישוב חודשי - תרחיש Calc_Pess
A3: חודש | B3: סה"כ | C3: 1 | D3: 2 | E3: 3 | F3: 4 | G3: 5 | H3: 6 | I3: 7 | J3: 8 | K3: 9 | L3: 10 | M3: 11 | N3: 12 | O3: 13 | P3: 14 | Q3: 15 | R3: 16 | S3: 17 | T3: 18 | U3: 19 | V3: 20 | W3: 21 | X3: 22 | Y3: 23 | Z3: 24
A4: -- שוק עברית --
A5: HE: התקנות אורגניות | B5: =SUM(C5:Z5) | C5: =Assumptions!$C$28*(1+Assumptions!$C$29)^(C$3-1) | D5: =Assumptions!$C$28*(1+Assumptions!$C$29)^(D$3-1) | E5: =Assumptions!$C$28*(1+Assumptions!$C$29)^(E$3-1) | F5: =Assumptions!$C$28*(1+Assumptions!$C$29)^(F$3-1) | G5: =Assumptions!$C$28*(1+Assumptions!$C$29)^(G$3-1) | H5: =Assumptions!$C$28*(1+Assumptions!$C$29)^(H$3-1) | I5: =Assumptions!$C$28*(1+Assumptions!$C$29)^(I$3-1) | J5: =Assumptions!$C$28*(1+Assumptions!$C$29)^(J$3-1) | ... Z5: =Assumptions!$C$28*(1+Assumptions!$C$29)^(Z$3-1)
A6: HE: הוצאת פרסום בתשלום (₪) | B6: =SUM(C6:Z6) | C6: =IF(AND(C$3>=Assumptions!$C$34,C$3<=Assumptions!$C$35),Assumptions!$C$33,0) | D6: =IF(AND(D$3>=Assumptions!$C$34,D$3<=Assumptions!$C$35),Assumptions!$C$33,0) | E6: =IF(AND(E$3>=Assumptions!$C$34,E$3<=Assumptions!$C$35),Assumptions!$C$33,0) | F6: =IF(AND(F$3>=Assumptions!$C$34,F$3<=Assumptions!$C$35),Assumptions!$C$33,0) | G6: =IF(AND(G$3>=Assumptions!$C$34,G$3<=Assumptions!$C$35),Assumptions!$C$33,0) | H6: =IF(AND(H$3>=Assumptions!$C$34,H$3<=Assumptions!$C$35),Assumptions!$C$33,0) | I6: =IF(AND(I$3>=Assumptions!$C$34,I$3<=Assumptions!$C$35),Assumptions!$C$33,0) | J6: =IF(AND(J$3>=Assumptions!$C$34,J$3<=Assumptions!$C$35),Assumptions!$C$33,0) | ... Z6: =IF(AND(Z$3>=Assumptions!$C$34,Z$3<=Assumptions!$C$35),Assumptions!$C$33,0)
A7: HE: התקנות מפרסום בתשלום | B7: =SUM(C7:Z7) | C7: =C6/Assumptions!$C$32 | D7: =D6/Assumptions!$C$32 | E7: =E6/Assumptions!$C$32 | F7: =F6/Assumptions!$C$32 | G7: =G6/Assumptions!$C$32 | H7: =H6/Assumptions!$C$32 | I7: =I6/Assumptions!$C$32 | J7: =J6/Assumptions!$C$32 | ... Z7: =Z6/Assumptions!$C$32
A8: HE: סה"כ התקנות | B8: =SUM(C8:Z8) | C8: =C5+C7 | D8: =D5+D7 | E8: =E5+E7 | F8: =F5+F7 | G8: =G5+G7 | H8: =H5+H7 | I8: =I5+I7 | J8: =J5+J7 | ... Z8: =Z5+Z7
A9: HE: שחקנים ותיקים (מחודש 2 ואילך, DAU) | C9: =0 | D9: =Assumptions!$C$40*C9+C8*Assumptions!$C$39 | E9: =Assumptions!$C$40*D9+D8*Assumptions!$C$39 | F9: =Assumptions!$C$40*E9+E8*Assumptions!$C$39 | G9: =Assumptions!$C$40*F9+F8*Assumptions!$C$39 | H9: =Assumptions!$C$40*G9+G8*Assumptions!$C$39 | I9: =Assumptions!$C$40*H9+H8*Assumptions!$C$39 | J9: =Assumptions!$C$40*I9+I8*Assumptions!$C$39 | K9: =Assumptions!$C$40*J9+J8*Assumptions!$C$39 | ... Z9: =Assumptions!$C$40*Y9+Y8*Assumptions!$C$39
A10: HE: DAU ממוצע | C10: =C8*((Assumptions!$C$37+Assumptions!$C$38+Assumptions!$C$39)/3)+C9 | D10: =D8*((Assumptions!$C$37+Assumptions!$C$38+Assumptions!$C$39)/3)+D9 | E10: =E8*((Assumptions!$C$37+Assumptions!$C$38+Assumptions!$C$39)/3)+E9 | F10: =F8*((Assumptions!$C$37+Assumptions!$C$38+Assumptions!$C$39)/3)+F9 | G10: =G8*((Assumptions!$C$37+Assumptions!$C$38+Assumptions!$C$39)/3)+G9 | H10: =H8*((Assumptions!$C$37+Assumptions!$C$38+Assumptions!$C$39)/3)+H9 | I10: =I8*((Assumptions!$C$37+Assumptions!$C$38+Assumptions!$C$39)/3)+I9 | J10: =J8*((Assumptions!$C$37+Assumptions!$C$38+Assumptions!$C$39)/3)+J9 | ... Z10: =Z8*((Assumptions!$C$37+Assumptions!$C$38+Assumptions!$C$39)/3)+Z9
A11: HE: משחקים בחודש | B11: =SUM(C11:Z11) | C11: =C10*Assumptions!$C$41*30 | D11: =D10*Assumptions!$C$41*30 | E11: =E10*Assumptions!$C$41*30 | F11: =F10*Assumptions!$C$41*30 | G11: =G10*Assumptions!$C$41*30 | H11: =H10*Assumptions!$C$41*30 | I11: =I10*Assumptions!$C$41*30 | J11: =J10*Assumptions!$C$41*30 | ... Z11: =Z10*Assumptions!$C$41*30
A12: HE: חשיפות ביניים | B12: =SUM(C12:Z12) | C12: =C11*Assumptions!$C$43*(1-Assumptions!$C$45)*(1-(Assumptions!$C$52*(Assumptions!$C$24+Assumptions!$C$26)))*Assumptions!$C$46 | D12: =D11*Assumptions!$C$43*(1-Assumptions!$C$45)*(1-(Assumptions!$C$52*(Assumptions!$C$24+Assumptions!$C$26)))*Assumptions!$C$46 | E12: =E11*Assumptions!$C$43*(1-Assumptions!$C$45)*(1-(Assumptions!$C$52*(Assumptions!$C$24+Assumptions!$C$26)))*Assumptions!$C$46 | F12: =F11*Assumptions!$C$43*(1-Assumptions!$C$45)*(1-(Assumptions!$C$52*(Assumptions!$C$24+Assumptions!$C$26)))*Assumptions!$C$46 | G12: =G11*Assumptions!$C$43*(1-Assumptions!$C$45)*(1-(Assumptions!$C$52*(Assumptions!$C$24+Assumptions!$C$26)))*Assumptions!$C$46 | H12: =H11*Assumptions!$C$43*(1-Assumptions!$C$45)*(1-(Assumptions!$C$52*(Assumptions!$C$24+Assumptions!$C$26)))*Assumptions!$C$46 | I12: =I11*Assumptions!$C$43*(1-Assumptions!$C$45)*(1-(Assumptions!$C$52*(Assumptions!$C$24+Assumptions!$C$26)))*Assumptions!$C$46 | J12: =J11*Assumptions!$C$43*(1-Assumptions!$C$45)*(1-(Assumptions!$C$52*(Assumptions!$C$24+Assumptions!$C$26)))*Assumptions!$C$46 | ... Z12: =Z11*Assumptions!$C$43*(1-Assumptions!$C$45)*(1-(Assumptions!$C$52*(Assumptions!$C$24+Assumptions!$C$26)))*Assumptions!$C$46
A13: HE: חשיפות מתוגמלות | B13: =SUM(C13:Z13) | C13: =C11*Assumptions!$C$44*Assumptions!$C$46 | D13: =D11*Assumptions!$C$44*Assumptions!$C$46 | E13: =E11*Assumptions!$C$44*Assumptions!$C$46 | F13: =F11*Assumptions!$C$44*Assumptions!$C$46 | G13: =G11*Assumptions!$C$44*Assumptions!$C$46 | H13: =H11*Assumptions!$C$44*Assumptions!$C$46 | I13: =I11*Assumptions!$C$44*Assumptions!$C$46 | J13: =J11*Assumptions!$C$44*Assumptions!$C$46 | ... Z13: =Z11*Assumptions!$C$44*Assumptions!$C$46
A14: HE: הכנסת פרסום ($) | B14: =SUM(C14:Z14) | C14: =(C12*Assumptions!$C$48+C13*Assumptions!$C$47)/1000 | D14: =(D12*Assumptions!$C$48+D13*Assumptions!$C$47)/1000 | E14: =(E12*Assumptions!$C$48+E13*Assumptions!$C$47)/1000 | F14: =(F12*Assumptions!$C$48+F13*Assumptions!$C$47)/1000 | G14: =(G12*Assumptions!$C$48+G13*Assumptions!$C$47)/1000 | H14: =(H12*Assumptions!$C$48+H13*Assumptions!$C$47)/1000 | I14: =(I12*Assumptions!$C$48+I13*Assumptions!$C$47)/1000 | J14: =(J12*Assumptions!$C$48+J13*Assumptions!$C$47)/1000 | ... Z14: =(Z12*Assumptions!$C$48+Z13*Assumptions!$C$47)/1000
A15: HE: הכנסת פרסום (₪) | B15: =SUM(C15:Z15) | C15: =C14*Assumptions!$C$22 | D15: =D14*Assumptions!$C$22 | E15: =E14*Assumptions!$C$22 | F15: =F14*Assumptions!$C$22 | G15: =G14*Assumptions!$C$22 | H15: =H14*Assumptions!$C$22 | I15: =I14*Assumptions!$C$22 | J15: =J14*Assumptions!$C$22 | ... Z15: =Z14*Assumptions!$C$22
A16: HE: רוכשי IAP | B16: =SUM(C16:Z16) | C16: =C8*Assumptions!$C$52 | D16: =D8*Assumptions!$C$52 | E16: =E8*Assumptions!$C$52 | F16: =F8*Assumptions!$C$52 | G16: =G8*Assumptions!$C$52 | H16: =H8*Assumptions!$C$52 | I16: =I8*Assumptions!$C$52 | J16: =J8*Assumptions!$C$52 | ... Z16: =Z8*Assumptions!$C$52
A17: HE: IAP ברוטו (₪, מחיר צרכן) | B17: =SUM(C17:Z17) | C17: =C16*(Assumptions!$C$24*Assumptions!$C$9+Assumptions!$C$25*Assumptions!$C$10+Assumptions!$C$26*Assumptions!$C$11) | D17: =D16*(Assumptions!$C$24*Assumptions!$C$9+Assumptions!$C$25*Assumptions!$C$10+Assumptions!$C$26*Assumptions!$C$11) | E17: =E16*(Assumptions!$C$24*Assumptions!$C$9+Assumptions!$C$25*Assumptions!$C$10+Assumptions!$C$26*Assumptions!$C$11) | F17: =F16*(Assumptions!$C$24*Assumptions!$C$9+Assumptions!$C$25*Assumptions!$C$10+Assumptions!$C$26*Assumptions!$C$11) | G17: =G16*(Assumptions!$C$24*Assumptions!$C$9+Assumptions!$C$25*Assumptions!$C$10+Assumptions!$C$26*Assumptions!$C$11) | H17: =H16*(Assumptions!$C$24*Assumptions!$C$9+Assumptions!$C$25*Assumptions!$C$10+Assumptions!$C$26*Assumptions!$C$11) | I17: =I16*(Assumptions!$C$24*Assumptions!$C$9+Assumptions!$C$25*Assumptions!$C$10+Assumptions!$C$26*Assumptions!$C$11) | J17: =J16*(Assumptions!$C$24*Assumptions!$C$9+Assumptions!$C$25*Assumptions!$C$10+Assumptions!$C$26*Assumptions!$C$11) | ... Z17: =Z16*(Assumptions!$C$24*Assumptions!$C$9+Assumptions!$C$25*Assumptions!$C$10+Assumptions!$C$26*Assumptions!$C$11)
A18: HE: IAP נטו אחרי מסים ועמלת חנות (₪) | B18: =SUM(C18:Z18) | C18: =C17/(1+Assumptions!$C$20)*(1-Assumptions!$C$19) | D18: =D17/(1+Assumptions!$C$20)*(1-Assumptions!$C$19) | E18: =E17/(1+Assumptions!$C$20)*(1-Assumptions!$C$19) | F18: =F17/(1+Assumptions!$C$20)*(1-Assumptions!$C$19) | G18: =G17/(1+Assumptions!$C$20)*(1-Assumptions!$C$19) | H18: =H17/(1+Assumptions!$C$20)*(1-Assumptions!$C$19) | I18: =I17/(1+Assumptions!$C$20)*(1-Assumptions!$C$19) | J18: =J17/(1+Assumptions!$C$20)*(1-Assumptions!$C$19) | ... Z18: =Z17/(1+Assumptions!$C$20)*(1-Assumptions!$C$19)
A19: -- B2B (ישראל, לפני מע"מ, ללא עמלת חנות) --
A20: B2B: הכנסה ממכירות חדשות (₪) | B20: =SUM(C20:Z20) | C20: =IF(C$3>=Assumptions!$C$54,Assumptions!$C$55*Assumptions!$C$16+Assumptions!$C$56*Assumptions!$C$15+Assumptions!$C$57*Assumptions!$C$17,0) | D20: =IF(D$3>=Assumptions!$C$54,Assumptions!$C$55*Assumptions!$C$16+Assumptions!$C$56*Assumptions!$C$15+Assumptions!$C$57*Assumptions!$C$17,0) | E20: =IF(E$3>=Assumptions!$C$54,Assumptions!$C$55*Assumptions!$C$16+Assumptions!$C$56*Assumptions!$C$15+Assumptions!$C$57*Assumptions!$C$17,0) | F20: =IF(F$3>=Assumptions!$C$54,Assumptions!$C$55*Assumptions!$C$16+Assumptions!$C$56*Assumptions!$C$15+Assumptions!$C$57*Assumptions!$C$17,0) | G20: =IF(G$3>=Assumptions!$C$54,Assumptions!$C$55*Assumptions!$C$16+Assumptions!$C$56*Assumptions!$C$15+Assumptions!$C$57*Assumptions!$C$17,0) | H20: =IF(H$3>=Assumptions!$C$54,Assumptions!$C$55*Assumptions!$C$16+Assumptions!$C$56*Assumptions!$C$15+Assumptions!$C$57*Assumptions!$C$17,0) | I20: =IF(I$3>=Assumptions!$C$54,Assumptions!$C$55*Assumptions!$C$16+Assumptions!$C$56*Assumptions!$C$15+Assumptions!$C$57*Assumptions!$C$17,0) | J20: =IF(J$3>=Assumptions!$C$54,Assumptions!$C$55*Assumptions!$C$16+Assumptions!$C$56*Assumptions!$C$15+Assumptions!$C$57*Assumptions!$C$17,0) | ... Z20: =IF(Z$3>=Assumptions!$C$54,Assumptions!$C$55*Assumptions!$C$16+Assumptions!$C$56*Assumptions!$C$15+Assumptions!$C$57*Assumptions!$C$17,0)
A21: B2B: הכנסה מחידושים (₪) | B21: =SUM(C21:Z21) | C21: =0 | D21: =0 | E21: =0 | F21: =0 | G21: =0 | H21: =0 | I21: =0 | J21: =0 | ... N21: =0 | O21: =Assumptions!$C$58*C20 | P21: =Assumptions!$C$58*D20 | Q21: =Assumptions!$C$58*E20 | R21: =Assumptions!$C$58*F20 | S21: =Assumptions!$C$58*G20 | T21: =Assumptions!$C$58*H20 | U21: =Assumptions!$C$58*I20 | V21: =Assumptions!$C$58*J20 | ... Z21: =Assumptions!$C$58*N20
A22: B2B: סה"כ הכנסה (₪) | B22: =SUM(C22:Z22) | C22: =C20+C21 | D22: =D20+D21 | E22: =E20+E21 | F22: =F20+F21 | G22: =G20+G21 | H22: =H20+H21 | I22: =I20+I21 | J22: =J20+J21 | ... Z22: =Z20+Z21
A24: -- שוק אנגלי (מחודש ההשקה) --
A25: EN: התקנות אורגניות | B25: =SUM(C25:Z25) | C25: =IF(C$3>=Assumptions!$C$31,Assumptions!$C$30*(1+Assumptions!$C$29)^(C$3-Assumptions!$C$31),0) | D25: =IF(D$3>=Assumptions!$C$31,Assumptions!$C$30*(1+Assumptions!$C$29)^(D$3-Assumptions!$C$31),0) | E25: =IF(E$3>=Assumptions!$C$31,Assumptions!$C$30*(1+Assumptions!$C$29)^(E$3-Assumptions!$C$31),0) | F25: =IF(F$3>=Assumptions!$C$31,Assumptions!$C$30*(1+Assumptions!$C$29)^(F$3-Assumptions!$C$31),0) | G25: =IF(G$3>=Assumptions!$C$31,Assumptions!$C$30*(1+Assumptions!$C$29)^(G$3-Assumptions!$C$31),0) | H25: =IF(H$3>=Assumptions!$C$31,Assumptions!$C$30*(1+Assumptions!$C$29)^(H$3-Assumptions!$C$31),0) | I25: =IF(I$3>=Assumptions!$C$31,Assumptions!$C$30*(1+Assumptions!$C$29)^(I$3-Assumptions!$C$31),0) | J25: =IF(J$3>=Assumptions!$C$31,Assumptions!$C$30*(1+Assumptions!$C$29)^(J$3-Assumptions!$C$31),0) | ... Z25: =IF(Z$3>=Assumptions!$C$31,Assumptions!$C$30*(1+Assumptions!$C$29)^(Z$3-Assumptions!$C$31),0)
A26: EN: הוצאת פרסום (אין) | B26: =SUM(C26:Z26) | C26: =0 | D26: =0 | E26: =0 | F26: =0 | G26: =0 | H26: =0 | I26: =0 | J26: =0 | ... Z26: =0
A27: EN: התקנות בתשלום (אין) | B27: =SUM(C27:Z27) | C27: =0 | D27: =0 | E27: =0 | F27: =0 | G27: =0 | H27: =0 | I27: =0 | J27: =0 | ... Z27: =0
A28: EN: סה"כ התקנות | B28: =SUM(C28:Z28) | C28: =C25+C27 | D28: =D25+D27 | E28: =E25+E27 | F28: =F25+F27 | G28: =G25+G27 | H28: =H25+H27 | I28: =I25+I27 | J28: =J25+J27 | ... Z28: =Z25+Z27
A29: EN: שחקנים ותיקים (מחודש 2 ואילך, DAU) | C29: =0 | D29: =Assumptions!$C$40*C29+C28*Assumptions!$C$39 | E29: =Assumptions!$C$40*D29+D28*Assumptions!$C$39 | F29: =Assumptions!$C$40*E29+E28*Assumptions!$C$39 | G29: =Assumptions!$C$40*F29+F28*Assumptions!$C$39 | H29: =Assumptions!$C$40*G29+G28*Assumptions!$C$39 | I29: =Assumptions!$C$40*H29+H28*Assumptions!$C$39 | J29: =Assumptions!$C$40*I29+I28*Assumptions!$C$39 | K29: =Assumptions!$C$40*J29+J28*Assumptions!$C$39 | ... Z29: =Assumptions!$C$40*Y29+Y28*Assumptions!$C$39
A30: EN: DAU ממוצע | C30: =C28*((Assumptions!$C$37+Assumptions!$C$38+Assumptions!$C$39)/3)+C29 | D30: =D28*((Assumptions!$C$37+Assumptions!$C$38+Assumptions!$C$39)/3)+D29 | E30: =E28*((Assumptions!$C$37+Assumptions!$C$38+Assumptions!$C$39)/3)+E29 | F30: =F28*((Assumptions!$C$37+Assumptions!$C$38+Assumptions!$C$39)/3)+F29 | G30: =G28*((Assumptions!$C$37+Assumptions!$C$38+Assumptions!$C$39)/3)+G29 | H30: =H28*((Assumptions!$C$37+Assumptions!$C$38+Assumptions!$C$39)/3)+H29 | I30: =I28*((Assumptions!$C$37+Assumptions!$C$38+Assumptions!$C$39)/3)+I29 | J30: =J28*((Assumptions!$C$37+Assumptions!$C$38+Assumptions!$C$39)/3)+J29 | ... Z30: =Z28*((Assumptions!$C$37+Assumptions!$C$38+Assumptions!$C$39)/3)+Z29
A31: EN: משחקים בחודש | B31: =SUM(C31:Z31) | C31: =C30*Assumptions!$C$41*30 | D31: =D30*Assumptions!$C$41*30 | E31: =E30*Assumptions!$C$41*30 | F31: =F30*Assumptions!$C$41*30 | G31: =G30*Assumptions!$C$41*30 | H31: =H30*Assumptions!$C$41*30 | I31: =I30*Assumptions!$C$41*30 | J31: =J30*Assumptions!$C$41*30 | ... Z31: =Z30*Assumptions!$C$41*30
A32: EN: חשיפות ביניים | B32: =SUM(C32:Z32) | C32: =C31*Assumptions!$C$43*(1-Assumptions!$C$45)*(1-(Assumptions!$C$52*(Assumptions!$C$24+Assumptions!$C$26)))*Assumptions!$C$46 | D32: =D31*Assumptions!$C$43*(1-Assumptions!$C$45)*(1-(Assumptions!$C$52*(Assumptions!$C$24+Assumptions!$C$26)))*Assumptions!$C$46 | E32: =E31*Assumptions!$C$43*(1-Assumptions!$C$45)*(1-(Assumptions!$C$52*(Assumptions!$C$24+Assumptions!$C$26)))*Assumptions!$C$46 | F32: =F31*Assumptions!$C$43*(1-Assumptions!$C$45)*(1-(Assumptions!$C$52*(Assumptions!$C$24+Assumptions!$C$26)))*Assumptions!$C$46 | G32: =G31*Assumptions!$C$43*(1-Assumptions!$C$45)*(1-(Assumptions!$C$52*(Assumptions!$C$24+Assumptions!$C$26)))*Assumptions!$C$46 | H32: =H31*Assumptions!$C$43*(1-Assumptions!$C$45)*(1-(Assumptions!$C$52*(Assumptions!$C$24+Assumptions!$C$26)))*Assumptions!$C$46 | I32: =I31*Assumptions!$C$43*(1-Assumptions!$C$45)*(1-(Assumptions!$C$52*(Assumptions!$C$24+Assumptions!$C$26)))*Assumptions!$C$46 | J32: =J31*Assumptions!$C$43*(1-Assumptions!$C$45)*(1-(Assumptions!$C$52*(Assumptions!$C$24+Assumptions!$C$26)))*Assumptions!$C$46 | ... Z32: =Z31*Assumptions!$C$43*(1-Assumptions!$C$45)*(1-(Assumptions!$C$52*(Assumptions!$C$24+Assumptions!$C$26)))*Assumptions!$C$46
A33: EN: חשיפות מתוגמלות | B33: =SUM(C33:Z33) | C33: =C31*Assumptions!$C$44*Assumptions!$C$46 | D33: =D31*Assumptions!$C$44*Assumptions!$C$46 | E33: =E31*Assumptions!$C$44*Assumptions!$C$46 | F33: =F31*Assumptions!$C$44*Assumptions!$C$46 | G33: =G31*Assumptions!$C$44*Assumptions!$C$46 | H33: =H31*Assumptions!$C$44*Assumptions!$C$46 | I33: =I31*Assumptions!$C$44*Assumptions!$C$46 | J33: =J31*Assumptions!$C$44*Assumptions!$C$46 | ... Z33: =Z31*Assumptions!$C$44*Assumptions!$C$46
A34: EN: הכנסת פרסום ($) | B34: =SUM(C34:Z34) | C34: =(C32*Assumptions!$C$50+C33*Assumptions!$C$49)/1000 | D34: =(D32*Assumptions!$C$50+D33*Assumptions!$C$49)/1000 | E34: =(E32*Assumptions!$C$50+E33*Assumptions!$C$49)/1000 | F34: =(F32*Assumptions!$C$50+F33*Assumptions!$C$49)/1000 | G34: =(G32*Assumptions!$C$50+G33*Assumptions!$C$49)/1000 | H34: =(H32*Assumptions!$C$50+H33*Assumptions!$C$49)/1000 | I34: =(I32*Assumptions!$C$50+I33*Assumptions!$C$49)/1000 | J34: =(J32*Assumptions!$C$50+J33*Assumptions!$C$49)/1000 | ... Z34: =(Z32*Assumptions!$C$50+Z33*Assumptions!$C$49)/1000
A35: EN: הכנסת פרסום (₪) | B35: =SUM(C35:Z35) | C35: =C34*Assumptions!$C$22 | D35: =D34*Assumptions!$C$22 | E35: =E34*Assumptions!$C$22 | F35: =F34*Assumptions!$C$22 | G35: =G34*Assumptions!$C$22 | H35: =H34*Assumptions!$C$22 | I35: =I34*Assumptions!$C$22 | J35: =J34*Assumptions!$C$22 | ... Z35: =Z34*Assumptions!$C$22
A36: EN: רוכשי IAP | B36: =SUM(C36:Z36) | C36: =C28*Assumptions!$C$52 | D36: =D28*Assumptions!$C$52 | E36: =E28*Assumptions!$C$52 | F36: =F28*Assumptions!$C$52 | G36: =G28*Assumptions!$C$52 | H36: =H28*Assumptions!$C$52 | I36: =I28*Assumptions!$C$52 | J36: =J28*Assumptions!$C$52 | ... Z36: =Z28*Assumptions!$C$52
A37: EN: IAP ברוטו (₪, מחיר צרכן) | B37: =SUM(C37:Z37) | C37: =C36*(Assumptions!$C$24*Assumptions!$C$12+Assumptions!$C$25*Assumptions!$C$13+Assumptions!$C$26*Assumptions!$C$14)*Assumptions!$C$22 | D37: =D36*(Assumptions!$C$24*Assumptions!$C$12+Assumptions!$C$25*Assumptions!$C$13+Assumptions!$C$26*Assumptions!$C$14)*Assumptions!$C$22 | E37: =E36*(Assumptions!$C$24*Assumptions!$C$12+Assumptions!$C$25*Assumptions!$C$13+Assumptions!$C$26*Assumptions!$C$14)*Assumptions!$C$22 | F37: =F36*(Assumptions!$C$24*Assumptions!$C$12+Assumptions!$C$25*Assumptions!$C$13+Assumptions!$C$26*Assumptions!$C$14)*Assumptions!$C$22 | G37: =G36*(Assumptions!$C$24*Assumptions!$C$12+Assumptions!$C$25*Assumptions!$C$13+Assumptions!$C$26*Assumptions!$C$14)*Assumptions!$C$22 | H37: =H36*(Assumptions!$C$24*Assumptions!$C$12+Assumptions!$C$25*Assumptions!$C$13+Assumptions!$C$26*Assumptions!$C$14)*Assumptions!$C$22 | I37: =I36*(Assumptions!$C$24*Assumptions!$C$12+Assumptions!$C$25*Assumptions!$C$13+Assumptions!$C$26*Assumptions!$C$14)*Assumptions!$C$22 | J37: =J36*(Assumptions!$C$24*Assumptions!$C$12+Assumptions!$C$25*Assumptions!$C$13+Assumptions!$C$26*Assumptions!$C$14)*Assumptions!$C$22 | ... Z37: =Z36*(Assumptions!$C$24*Assumptions!$C$12+Assumptions!$C$25*Assumptions!$C$13+Assumptions!$C$26*Assumptions!$C$14)*Assumptions!$C$22
A38: EN: IAP נטו אחרי מסים ועמלת חנות (₪) | B38: =SUM(C38:Z38) | C38: =C37*(1-Assumptions!$C$21)*(1-Assumptions!$C$19) | D38: =D37*(1-Assumptions!$C$21)*(1-Assumptions!$C$19) | E38: =E37*(1-Assumptions!$C$21)*(1-Assumptions!$C$19) | F38: =F37*(1-Assumptions!$C$21)*(1-Assumptions!$C$19) | G38: =G37*(1-Assumptions!$C$21)*(1-Assumptions!$C$19) | H38: =H37*(1-Assumptions!$C$21)*(1-Assumptions!$C$19) | I38: =I37*(1-Assumptions!$C$21)*(1-Assumptions!$C$19) | J38: =J37*(1-Assumptions!$C$21)*(1-Assumptions!$C$19) | ... Z38: =Z37*(1-Assumptions!$C$21)*(1-Assumptions!$C$19)
A40: -- סיכום --
A41: הכנסות - עברית בלבד (פרסום + IAP נטו + B2B) | B41: =SUM(C41:Z41) | C41: =C15+C18+C22 | D41: =D15+D18+D22 | E41: =E15+E18+E22 | F41: =F15+F18+F22 | G41: =G15+G18+G22 | H41: =H15+H18+H22 | I41: =I15+I18+I22 | J41: =J15+J18+J22 | ... Z41: =Z15+Z18+Z22
A42: הכנסות שוק אנגלי (פרסום + IAP נטו) | B42: =SUM(C42:Z42) | C42: =C35+C38 | D42: =D35+D38 | E42: =E35+E38 | F42: =F35+F38 | G42: =G35+G38 | H42: =H35+H38 | I42: =I35+I38 | J42: =J35+J38 | ... Z42: =Z35+Z38
A43: הכנסות - עברית+אנגלית | B43: =SUM(C43:Z43) | C43: =C41+C42 | D43: =D41+D42 | E43: =E41+E42 | F43: =F41+F42 | G43: =G41+G42 | H43: =H41+H42 | I43: =I41+I42 | J43: =J41+J42 | ... Z43: =Z41+Z42
...

Sheet Calc_Base
A1: חישוב חודשי - תרחיש Calc_Base
A3: חודש | B3: סה"כ | C3: 1 | D3: 2 | E3: 3 | F3: 4 | G3: 5 | H3: 6 | I3: 7 | J3: 8 | K3: 9 | L3: 10 | M3: 11 | N3: 12 | O3: 13 | P3: 14 | Q3: 15 | R3: 16 | S3: 17 | T3: 18 | U3: 19 | V3: 20 | W3: 21 | X3: 22 | Y3: 23 | Z3: 24
A4: -- שוק עברית --
A5: HE: התקנות אורגניות | B5: =SUM(C5:Z5) | C5: =Assumptions!$D$28*(1+Assumptions!$D$29)^(C$3-1) | D5: =Assumptions!$D$28*(1+Assumptions!$D$29)^(D$3-1) | E5: =Assumptions!$D$28*(1+Assumptions!$D$29)^(E$3-1) | F5: =Assumptions!$D$28*(1+Assumptions!$D$29)^(F$3-1) | G5: =Assumptions!$D$28*(1+Assumptions!$D$29)^(G$3-1) | H5: =Assumptions!$D$28*(1+Assumptions!$D$29)^(H$3-1) | I5: =Assumptions!$D$28*(1+Assumptions!$D$29)^(I$3-1) | J5: =Assumptions!$D$28*(1+Assumptions!$D$29)^(J$3-1) | ... Z5: =Assumptions!$D$28*(1+Assumptions!$D$29)^(Z$3-1)
A6: HE: הוצאת פרסום בתשלום (₪) | B6: =SUM(C6:Z6) | C6: =IF(AND(C$3>=Assumptions!$D$34,C$3<=Assumptions!$D$35),Assumptions!$D$33,0) | D6: =IF(AND(D$3>=Assumptions!$D$34,D$3<=Assumptions!$D$35),Assumptions!$D$33,0) | E6: =IF(AND(E$3>=Assumptions!$D$34,E$3<=Assumptions!$D$35),Assumptions!$D$33,0) | F6: =IF(AND(F$3>=Assumptions!$D$34,F$3<=Assumptions!$D$35),Assumptions!$D$33,0) | G6: =IF(AND(G$3>=Assumptions!$D$34,G$3<=Assumptions!$D$35),Assumptions!$D$33,0) | H6: =IF(AND(H$3>=Assumptions!$D$34,H$3<=Assumptions!$D$35),Assumptions!$D$33,0) | I6: =IF(AND(I$3>=Assumptions!$D$34,I$3<=Assumptions!$D$35),Assumptions!$D$33,0) | J6: =IF(AND(J$3>=Assumptions!$D$34,J$3<=Assumptions!$D$35),Assumptions!$D$33,0) | ... Z6: =IF(AND(Z$3>=Assumptions!$D$34,Z$3<=Assumptions!$D$35),Assumptions!$D$33,0)
A7: HE: התקנות מפרסום בתשלום | B7: =SUM(C7:Z7) | C7: =C6/Assumptions!$D$32 | D7: =D6/Assumptions!$D$32 | E7: =E6/Assumptions!$D$32 | F7: =F6/Assumptions!$D$32 | G7: =G6/Assumptions!$D$32 | H7: =H6/Assumptions!$D$32 | I7: =I6/Assumptions!$D$32 | J7: =J6/Assumptions!$D$32 | ... Z7: =Z6/Assumptions!$D$32
A8: HE: סה"כ התקנות | B8: =SUM(C8:Z8) | C8: =C5+C7 | D8: =D5+D7 | E8: =E5+E7 | F8: =F5+F7 | G8: =G5+G7 | H8: =H5+H7 | I8: =I5+I7 | J8: =J5+J7 | ... Z8: =Z5+Z7
A9: HE: שחקנים ותיקים (מחודש 2 ואילך, DAU) | C9: =0 | D9: =Assumptions!$D$40*C9+C8*Assumptions!$D$39 | E9: =Assumptions!$D$40*D9+D8*Assumptions!$D$39 | F9: =Assumptions!$D$40*E9+E8*Assumptions!$D$39 | G9: =Assumptions!$D$40*F9+F8*Assumptions!$D$39 | H9: =Assumptions!$D$40*G9+G8*Assumptions!$D$39 | I9: =Assumptions!$D$40*H9+H8*Assumptions!$D$39 | J9: =Assumptions!$D$40*I9+I8*Assumptions!$D$39 | K9: =Assumptions!$D$40*J9+J8*Assumptions!$D$39 | ... Z9: =Assumptions!$D$40*Y9+Y8*Assumptions!$D$39
A10: HE: DAU ממוצע | C10: =C8*((Assumptions!$D$37+Assumptions!$D$38+Assumptions!$D$39)/3)+C9 | D10: =D8*((Assumptions!$D$37+Assumptions!$D$38+Assumptions!$D$39)/3)+D9 | E10: =E8*((Assumptions!$D$37+Assumptions!$D$38+Assumptions!$D$39)/3)+E9 | F10: =F8*((Assumptions!$D$37+Assumptions!$D$38+Assumptions!$D$39)/3)+F9 | G10: =G8*((Assumptions!$D$37+Assumptions!$D$38+Assumptions!$D$39)/3)+G9 | H10: =H8*((Assumptions!$D$37+Assumptions!$D$38+Assumptions!$D$39)/3)+H9 | I10: =I8*((Assumptions!$D$37+Assumptions!$D$38+Assumptions!$D$39)/3)+I9 | J10: =J8*((Assumptions!$D$37+Assumptions!$D$38+Assumptions!$D$39)/3)+J9 | ... Z10: =Z8*((Assumptions!$D$37+Assumptions!$D$38+Assumptions!$D$39)/3)+Z9
A11: HE: משחקים בחודש | B11: =SUM(C11:Z11) | C11: =C10*Assumptions!$D$41*30 | D11: =D10*Assumptions!$D$41*30 | E11: =E10*Assumptions!$D$41*30 | F11: =F10*Assumptions!$D$41*30 | G11: =G10*Assumptions!$D$41*30 | H11: =H10*Assumptions!$D$41*30 | I11: =I10*Assumptions!$D$41*30 | J11: =J10*Assumptions!$D$41*30 | ... Z11: =Z10*Assumptions!$D$41*30
A12: HE: חשיפות ביניים | B12: =SUM(C12:Z12) | C12: =C11*Assumptions!$D$43*(1-Assumptions!$D$45)*(1-(Assumptions!$D$52*(Assumptions!$D$24+Assumptions!$D$26)))*Assumptions!$D$46 | D12: =D11*Assumptions!$D$43*(1-Assumptions!$D$45)*(1-(Assumptions!$D$52*(Assumptions!$D$24+Assumptions!$D$26)))*Assumptions!$D$46 | E12: =E11*Assumptions!$D$43*(1-Assumptions!$D$45)*(1-(Assumptions!$D$52*(Assumptions!$D$24+Assumptions!$D$26)))*Assumptions!$D$46 | F12: =F11*Assumptions!$D$43*(1-Assumptions!$D$45)*(1-(Assumptions!$D$52*(Assumptions!$D$24+Assumptions!$D$26)))*Assumptions!$D$46 | G12: =G11*Assumptions!$D$43*(1-Assumptions!$D$45)*(1-(Assumptions!$D$52*(Assumptions!$D$24+Assumptions!$D$26)))*Assumptions!$D$46 | H12: =H11*Assumptions!$D$43*(1-Assumptions!$D$45)*(1-(Assumptions!$D$52*(Assumptions!$D$24+Assumptions!$D$26)))*Assumptions!$D$46 | I12: =I11*Assumptions!$D$43*(1-Assumptions!$D$45)*(1-(Assumptions!$D$52*(Assumptions!$D$24+Assumptions!$D$26)))*Assumptions!$D$46 | J12: =J11*Assumptions!$D$43*(1-Assumptions!$D$45)*(1-(Assumptions!$D$52*(Assumptions!$D$24+Assumptions!$D$26)))*Assumptions!$D$46 | ... Z12: =Z11*Assumptions!$D$43*(1-Assumptions!$D$45)*(1-(Assumptions!$D$52*(Assumptions!$D$24+Assumptions!$D$26)))*Assumptions!$D$46
A13: HE: חשיפות מתוגמלות | B13: =SUM(C13:Z13) | C13: =C11*Assumptions!$D$44*Assumptions!$D$46 | D13: =D11*Assumptions!$D$44*Assumptions!$D$46 | E13: =E11*Assumptions!$D$44*Assumptions!$D$46 | F13: =F11*Assumptions!$D$44*Assumptions!$D$46 | G13: =G11*Assumptions!$D$44*Assumptions!$D$46 | H13: =H11*Assumptions!$D$44*Assumptions!$D$46 | I13: =I11*Assumptions!$D$44*Assumptions!$D$46 | J13: =J11*Assumptions!$D$44*Assumptions!$D$46 | ... Z13: =Z11*Assumptions!$D$44*Assumptions!$D$46
A14: HE: הכנסת פרסום ($) | B14: =SUM(C14:Z14) | C14: =(C12*Assumptions!$D$48+C13*Assumptions!$D$47)/1000 | D14: =(D12*Assumptions!$D$48+D13*Assumptions!$D$47)/1000 | E14: =(E12*Assumptions!$D$48+E13*Assumptions!$D$47)/1000 | F14: =(F12*Assumptions!$D$48+F13*Assumptions!$D$47)/1000 | G14: =(G12*Assumptions!$D$48+G13*Assumptions!$D$47)/1000 | H14: =(H12*Assumptions!$D$48+H13*Assumptions!$D$47)/1000 | I14: =(I12*Assumptions!$D$48+I13*Assumptions!$D$47)/1000 | J14: =(J12*Assumptions!$D$48+J13*Assumptions!$D$47)/1000 | ... Z14: =(Z12*Assumptions!$D$48+Z13*Assumptions!$D$47)/1000
A15: HE: הכנסת פרסום (₪) | B15: =SUM(C15:Z15) | C15: =C14*Assumptions!$D$22 | D15: =D14*Assumptions!$D$22 | E15: =E14*Assumptions!$D$22 | F15: =F14*Assumptions!$D$22 | G15: =G14*Assumptions!$D$22 | H15: =H14*Assumptions!$D$22 | I15: =I14*Assumptions!$D$22 | J15: =J14*Assumptions!$D$22 | ... Z15: =Z14*Assumptions!$D$22
A16: HE: רוכשי IAP | B16: =SUM(C16:Z16) | C16: =C8*Assumptions!$D$52 | D16: =D8*Assumptions!$D$52 | E16: =E8*Assumptions!$D$52 | F16: =F8*Assumptions!$D$52 | G16: =G8*Assumptions!$D$52 | H16: =H8*Assumptions!$D$52 | I16: =I8*Assumptions!$D$52 | J16: =J8*Assumptions!$D$52 | ... Z16: =Z8*Assumptions!$D$52
A17: HE: IAP ברוטו (₪, מחיר צרכן) | B17: =SUM(C17:Z17) | C17: =C16*(Assumptions!$D$24*Assumptions!$D$9+Assumptions!$D$25*Assumptions!$D$10+Assumptions!$D$26*Assumptions!$D$11) | D17: =D16*(Assumptions!$D$24*Assumptions!$D$9+Assumptions!$D$25*Assumptions!$D$10+Assumptions!$D$26*Assumptions!$D$11) | E17: =E16*(Assumptions!$D$24*Assumptions!$D$9+Assumptions!$D$25*Assumptions!$D$10+Assumptions!$D$26*Assumptions!$D$11) | F17: =F16*(Assumptions!$D$24*Assumptions!$D$9+Assumptions!$D$25*Assumptions!$D$10+Assumptions!$D$26*Assumptions!$D$11) | G17: =G16*(Assumptions!$D$24*Assumptions!$D$9+Assumptions!$D$25*Assumptions!$D$10+Assumptions!$D$26*Assumptions!$D$11) | H17: =H16*(Assumptions!$D$24*Assumptions!$D$9+Assumptions!$D$25*Assumptions!$D$10+Assumptions!$D$26*Assumptions!$D$11) | I17: =I16*(Assumptions!$D$24*Assumptions!$D$9+Assumptions!$D$25*Assumptions!$D$10+Assumptions!$D$26*Assumptions!$D$11) | J17: =J16*(Assumptions!$D$24*Assumptions!$D$9+Assumptions!$D$25*Assumptions!$D$10+Assumptions!$D$26*Assumptions!$D$11) | ... Z17: =Z16*(Assumptions!$D$24*Assumptions!$D$9+Assumptions!$D$25*Assumptions!$D$10+Assumptions!$D$26*Assumptions!$D$11)
A18: HE: IAP נטו אחרי מסים ועמלת חנות (₪) | B18: =SUM(C18:Z18) | C18: =C17/(1+Assumptions!$D$20)*(1-Assumptions!$D$19) | D18: =D17/(1+Assumptions!$D$20)*(1-Assumptions!$D$19) | E18: =E17/(1+Assumptions!$D$20)*(1-Assumptions!$D$19) | F18: =F17/(1+Assumptions!$D$20)*(1-Assumptions!$D$19) | G18: =G17/(1+Assumptions!$D$20)*(1-Assumptions!$D$19) | H18: =H17/(1+Assumptions!$D$20)*(1-Assumptions!$D$19) | I18: =I17/(1+Assumptions!$D$20)*(1-Assumptions!$D$19) | J18: =J17/(1+Assumptions!$D$20)*(1-Assumptions!$D$19) | ... Z18: =Z17/(1+Assumptions!$D$20)*(1-Assumptions!$D$19)
A19: -- B2B (ישראל, לפני מע"מ, ללא עמלת חנות) --
A20: B2B: הכנסה ממכירות חדשות (₪) | B20: =SUM(C20:Z20) | C20: =IF(C$3>=Assumptions!$D$54,Assumptions!$D$55*Assumptions!$D$16+Assumptions!$D$56*Assumptions!$D$15+Assumptions!$D$57*Assumptions!$D$17,0) | D20: =IF(D$3>=Assumptions!$D$54,Assumptions!$D$55*Assumptions!$D$16+Assumptions!$D$56*Assumptions!$D$15+Assumptions!$D$57*Assumptions!$D$17,0) | E20: =IF(E$3>=Assumptions!$D$54,Assumptions!$D$55*Assumptions!$D$16+Assumptions!$D$56*Assumptions!$D$15+Assumptions!$D$57*Assumptions!$D$17,0) | F20: =IF(F$3>=Assumptions!$D$54,Assumptions!$D$55*Assumptions!$D$16+Assumptions!$D$56*Assumptions!$D$15+Assumptions!$D$57*Assumptions!$D$17,0) | G20: =IF(G$3>=Assumptions!$D$54,Assumptions!$D$55*Assumptions!$D$16+Assumptions!$D$56*Assumptions!$D$15+Assumptions!$D$57*Assumptions!$D$17,0) | H20: =IF(H$3>=Assumptions!$D$54,Assumptions!$D$55*Assumptions!$D$16+Assumptions!$D$56*Assumptions!$D$15+Assumptions!$D$57*Assumptions!$D$17,0) | I20: =IF(I$3>=Assumptions!$D$54,Assumptions!$D$55*Assumptions!$D$16+Assumptions!$D$56*Assumptions!$D$15+Assumptions!$D$57*Assumptions!$D$17,0) | J20: =IF(J$3>=Assumptions!$D$54,Assumptions!$D$55*Assumptions!$D$16+Assumptions!$D$56*Assumptions!$D$15+Assumptions!$D$57*Assumptions!$D$17,0) | ... Z20: =IF(Z$3>=Assumptions!$D$54,Assumptions!$D$55*Assumptions!$D$16+Assumptions!$D$56*Assumptions!$D$15+Assumptions!$D$57*Assumptions!$D$17,0)
A21: B2B: הכנסה מחידושים (₪) | B21: =SUM(C21:Z21) | C21: =0 | D21: =0 | E21: =0 | F21: =0 | G21: =0 | H21: =0 | I21: =0 | J21: =0 | ... N21: =0 | O21: =Assumptions!$D$58*C20 | P21: =Assumptions!$D$58*D20 | Q21: =Assumptions!$D$58*E20 | R21: =Assumptions!$D$58*F20 | S21: =Assumptions!$D$58*G20 | T21: =Assumptions!$D$58*H20 | U21: =Assumptions!$D$58*I20 | V21: =Assumptions!$D$58*J20 | ... Z21: =Assumptions!$D$58*N20
A22: B2B: סה"כ הכנסה (₪) | B22: =SUM(C22:Z22) | C22: =C20+C21 | D22: =D20+D21 | E22: =E20+E21 | F22: =F20+F21 | G22: =G20+G21 | H22: =H20+H21 | I22: =I20+I21 | J22: =J20+J21 | ... Z22: =Z20+Z21
A24: -- שוק אנגלי (מחודש ההשקה) --
A25: EN: התקנות אורגניות | B25: =SUM(C25:Z25) | C25: =IF(C$3>=Assumptions!$D$31,Assumptions!$D$30*(1+Assumptions!$D$29)^(C$3-Assumptions!$D$31),0) | D25: =IF(D$3>=Assumptions!$D$31,Assumptions!$D$30*(1+Assumptions!$D$29)^(D$3-Assumptions!$D$31),0) | E25: =IF(E$3>=Assumptions!$D$31,Assumptions!$D$30*(1+Assumptions!$D$29)^(E$3-Assumptions!$D$31),0) | F25: =IF(F$3>=Assumptions!$D$31,Assumptions!$D$30*(1+Assumptions!$D$29)^(F$3-Assumptions!$D$31),0) | G25: =IF(G$3>=Assumptions!$D$31,Assumptions!$D$30*(1+Assumptions!$D$29)^(G$3-Assumptions!$D$31),0) | H25: =IF(H$3>=Assumptions!$D$31,Assumptions!$D$30*(1+Assumptions!$D$29)^(H$3-Assumptions!$D$31),0) | I25: =IF(I$3>=Assumptions!$D$31,Assumptions!$D$30*(1+Assumptions!$D$29)^(I$3-Assumptions!$D$31),0) | J25: =IF(J$3>=Assumptions!$D$31,Assumptions!$D$30*(1+Assumptions!$D$29)^(J$3-Assumptions!$D$31),0) | ... Z25: =IF(Z$3>=Assumptions!$D$31,Assumptions!$D$30*(1+Assumptions!$D$29)^(Z$3-Assumptions!$D$31),0)
A26: EN: הוצאת פרסום (אין) | B26: =SUM(C26:Z26) | C26: =0 | D26: =0 | E26: =0 | F26: =0 | G26: =0 | H26: =0 | I26: =0 | J26: =0 | ... Z26: =0
A27: EN: התקנות בתשלום (אין) | B27: =SUM(C27:Z27) | C27: =0 | D27: =0 | E27: =0 | F27: =0 | G27: =0 | H27: =0 | I27: =0 | J27: =0 | ... Z27: =0
A28: EN: סה"כ התקנות | B28: =SUM(C28:Z28) | C28: =C25+C27 | D28: =D25+D27 | E28: =E25+E27 | F28: =F25+F27 | G28: =G25+G27 | H28: =H25+H27 | I28: =I25+I27 | J28: =J25+J27 | ... Z28: =Z25+Z27
A29: EN: שחקנים ותיקים (מחודש 2 ואילך, DAU) | C29: =0 | D29: =Assumptions!$D$40*C29+C28*Assumptions!$D$39 | E29: =Assumptions!$D$40*D29+D28*Assumptions!$D$39 | F29: =Assumptions!$D$40*E29+E28*Assumptions!$D$39 | G29: =Assumptions!$D$40*F29+F28*Assumptions!$D$39 | H29: =Assumptions!$D$40*G29+G28*Assumptions!$D$39 | I29: =Assumptions!$D$40*H29+H28*Assumptions!$D$39 | J29: =Assumptions!$D$40*I29+I28*Assumptions!$D$39 | K29: =Assumptions!$D$40*J29+J28*Assumptions!$D$39 | ... Z29: =Assumptions!$D$40*Y29+Y28*Assumptions!$D$39
A30: EN: DAU ממוצע | C30: =C28*((Assumptions!$D$37+Assumptions!$D$38+Assumptions!$D$39)/3)+C29 | D30: =D28*((Assumptions!$D$37+Assumptions!$D$38+Assumptions!$D$39)/3)+D29 | E30: =E28*((Assumptions!$D$37+Assumptions!$D$38+Assumptions!$D$39)/3)+E29 | F30: =F28*((Assumptions!$D$37+Assumptions!$D$38+Assumptions!$D$39)/3)+F29 | G30: =G28*((Assumptions!$D$37+Assumptions!$D$38+Assumptions!$D$39)/3)+G29 | H30: =H28*((Assumptions!$D$37+Assumptions!$D$38+Assumptions!$D$39)/3)+H29 | I30: =I28*((Assumptions!$D$37+Assumptions!$D$38+Assumptions!$D$39)/3)+I29 | J30: =J28*((Assumptions!$D$37+Assumptions!$D$38+Assumptions!$D$39)/3)+J29 | ... Z30: =Z28*((Assumptions!$D$37+Assumptions!$D$38+Assumptions!$D$39)/3)+Z29
A31: EN: משחקים בחודש | B31: =SUM(C31:Z31) | C31: =C30*Assumptions!$D$41*30 | D31: =D30*Assumptions!$D$41*30 | E31: =E30*Assumptions!$D$41*30 | F31: =F30*Assumptions!$D$41*30 | G31: =G30*Assumptions!$D$41*30 | H31: =H30*Assumptions!$D$41*30 | I31: =I30*Assumptions!$D$41*30 | J31: =J30*Assumptions!$D$41*30 | ... Z31: =Z30*Assumptions!$D$41*30
A32: EN: חשיפות ביניים | B32: =SUM(C32:Z32) | C32: =C31*Assumptions!$D$43*(1-Assumptions!$D$45)*(1-(Assumptions!$D$52*(Assumptions!$D$24+Assumptions!$D$26)))*Assumptions!$D$46 | D32: =D31*Assumptions!$D$43*(1-Assumptions!$D$45)*(1-(Assumptions!$D$52*(Assumptions!$D$24+Assumptions!$D$26)))*Assumptions!$D$46 | E32: =E31*Assumptions!$D$43*(1-Assumptions!$D$45)*(1-(Assumptions!$D$52*(Assumptions!$D$24+Assumptions!$D$26)))*Assumptions!$D$46 | F32: =F31*Assumptions!$D$43*(1-Assumptions!$D$45)*(1-(Assumptions!$D$52*(Assumptions!$D$24+Assumptions!$D$26)))*Assumptions!$D$46 | G32: =G31*Assumptions!$D$43*(1-Assumptions!$D$45)*(1-(Assumptions!$D$52*(Assumptions!$D$24+Assumptions!$D$26)))*Assumptions!$D$46 | H32: =H31*Assumptions!$D$43*(1-Assumptions!$D$45)*(1-(Assumptions!$D$52*(Assumptions!$D$24+Assumptions!$D$26)))*Assumptions!$D$46 | I32: =I31*Assumptions!$D$43*(1-Assumptions!$D$45)*(1-(Assumptions!$D$52*(Assumptions!$D$24+Assumptions!$D$26)))*Assumptions!$D$46 | J32: =J31*Assumptions!$D$43*(1-Assumptions!$D$45)*(1-(Assumptions!$D$52*(Assumptions!$D$24+Assumptions!$D$26)))*Assumptions!$D$46 | ... Z32: =Z31*Assumptions!$D$43*(1-Assumptions!$D$45)*(1-(Assumptions!$D$52*(Assumptions!$D$24+Assumptions!$D$26)))*Assumptions!$D$46
A33: EN: חשיפות מתוגמלות | B33: =SUM(C33:Z33) | C33: =C31*Assumptions!$D$44*Assumptions!$D$46 | D33: =D31*Assumptions!$D$44*Assumptions!$D$46 | E33: =E31*Assumptions!$D$44*Assumptions!$D$46 | F33: =F31*Assumptions!$D$44*Assumptions!$D$46 | G33: =G31*Assumptions!$D$44*Assumptions!$D$46 | H33: =H31*Assumptions!$D$44*Assumptions!$D$46 | I33: =I31*Assumptions!$D$44*Assumptions!$D$46 | J33: =J31*Assumptions!$D$44*Assumptions!$D$46 | ... Z33: =Z31*Assumptions!$D$44*Assumptions!$D$46
A34: EN: הכנסת פרסום ($) | B34: =SUM(C34:Z34) | C34: =(C32*Assumptions!$D$50+C33*Assumptions!$D$49)/1000 | D34: =(D32*Assumptions!$D$50+D33*Assumptions!$D$49)/1000 | E34: =(E32*Assumptions!$D$50+E33*Assumptions!$D$49)/1000 | F34: =(F32*Assumptions!$D$50+F33*Assumptions!$D$49)/1000 | G34: =(G32*Assumptions!$D$50+G33*Assumptions!$D$49)/1000 | H34: =(H32*Assumptions!$D$50+H33*Assumptions!$D$49)/1000 | I34: =(I32*Assumptions!$D$50+I33*Assumptions!$D$49)/1000 | J34: =(J32*Assumptions!$D$50+J33*Assumptions!$D$49)/1000 | ... Z34: =(Z32*Assumptions!$D$50+Z33*Assumptions!$D$49)/1000
A35: EN: הכנסת פרסום (₪) | B35: =SUM(C35:Z35) | C35: =C34*Assumptions!$D$22 | D35: =D34*Assumptions!$D$22 | E35: =E34*Assumptions!$D$22 | F35: =F34*Assumptions!$D$22 | G35: =G34*Assumptions!$D$22 | H35: =H34*Assumptions!$D$22 | I35: =I34*Assumptions!$D$22 | J35: =J34*Assumptions!$D$22 | ... Z35: =Z34*Assumptions!$D$22
A36: EN: רוכשי IAP | B36: =SUM(C36:Z36) | C36: =C28*Assumptions!$D$52 | D36: =D28*Assumptions!$D$52 | E36: =E28*Assumptions!$D$52 | F36: =F28*Assumptions!$D$52 | G36: =G28*Assumptions!$D$52 | H36: =H28*Assumptions!$D$52 | I36: =I28*Assumptions!$D$52 | J36: =J28*Assumptions!$D$52 | ... Z36: =Z28*Assumptions!$D$52
A37: EN: IAP ברוטו (₪, מחיר צרכן) | B37: =SUM(C37:Z37) | C37: =C36*(Assumptions!$D$24*Assumptions!$D$12+Assumptions!$D$25*Assumptions!$D$13+Assumptions!$D$26*Assumptions!$D$14)*Assumptions!$D$22 | D37: =D36*(Assumptions!$D$24*Assumptions!$D$12+Assumptions!$D$25*Assumptions!$D$13+Assumptions!$D$26*Assumptions!$D$14)*Assumptions!$D$22 | E37: =E36*(Assumptions!$D$24*Assumptions!$D$12+Assumptions!$D$25*Assumptions!$D$13+Assumptions!$D$26*Assumptions!$D$14)*Assumptions!$D$22 | F37: =F36*(Assumptions!$D$24*Assumptions!$D$12+Assumptions!$D$25*Assumptions!$D$13+Assumptions!$D$26*Assumptions!$D$14)*Assumptions!$D$22 | G37: =G36*(Assumptions!$D$24*Assumptions!$D$12+Assumptions!$D$25*Assumptions!$D$13+Assumptions!$D$26*Assumptions!$D$14)*Assumptions!$D$22 | H37: =H36*(Assumptions!$D$24*Assumptions!$D$12+Assumptions!$D$25*Assumptions!$D$13+Assumptions!$D$26*Assumptions!$D$14)*Assumptions!$D$22 | I37: =I36*(Assumptions!$D$24*Assumptions!$D$12+Assumptions!$D$25*Assumptions!$D$13+Assumptions!$D$26*Assumptions!$D$14)*Assumptions!$D$22 | J37: =J36*(Assumptions!$D$24*Assumptions!$D$12+Assumptions!$D$25*Assumptions!$D$13+Assumptions!$D$26*Assumptions!$D$14)*Assumptions!$D$22 | ... Z37: =Z36*(Assumptions!$D$24*Assumptions!$D$12+Assumptions!$D$25*Assumptions!$D$13+Assumptions!$D$26*Assumptions!$D$14)*Assumptions!$D$22
A38: EN: IAP נטו אחרי מסים ועמלת חנות (₪) | B38: =SUM(C38:Z38) | C38: =C37*(1-Assumptions!$D$21)*(1-Assumptions!$D$19) | D38: =D37*(1-Assumptions!$D$21)*(1-Assumptions!$D$19) | E38: =E37*(1-Assumptions!$D$21)*(1-Assumptions!$D$19) | F38: =F37*(1-Assumptions!$D$21)*(1-Assumptions!$D$19) | G38: =G37*(1-Assumptions!$D$21)*(1-Assumptions!$D$19) | H38: =H37*(1-Assumptions!$D$21)*(1-Assumptions!$D$19) | I38: =I37*(1-Assumptions!$D$21)*(1-Assumptions!$D$19) | J38: =J37*(1-Assumptions!$D$21)*(1-Assumptions!$D$19) | ... Z38: =Z37*(1-Assumptions!$D$21)*(1-Assumptions!$D$19)
A40: -- סיכום --
